[ERROR 2022-04-06 01:36:04,812] worker.py: 428  SystemExit was raised from the worker
Traceback (most recent call last):
  File "python/ray/_raylet.pyx", line 640, in ray._raylet.task_execution_handler
  File "python/ray/_raylet.pyx", line 488, in ray._raylet.execute_task
  File "python/ray/_raylet.pyx", line 525, in ray._raylet.execute_task
  File "python/ray/_raylet.pyx", line 532, in ray._raylet.execute_task
  File "python/ray/_raylet.pyx", line 536, in ray._raylet.execute_task
  File "python/ray/_raylet.pyx", line 486, in ray._raylet.execute_task.function_executor
  File "/home/qc_whaley/anaconda3/envs/tf2.6/lib/python3.9/site-packages/ray/_private/function_manager.py", line 563, in actor_method_executor
    return method(__ray_actor, *args, **kwargs)
  File "/home/qc_whaley/anaconda3/envs/tf2.6/lib/python3.9/site-packages/ray/tune/trainable.py", line 103, in __init__
    self.setup(copy.deepcopy(self.config))
  File "/home/qc_whaley/dephased_ttn_project/uni_ttn/tf2.7/non_distributed_tunning/model.py", line 218, in setup
    self.model = Model(data_path, digits, val_split, deph_p, num_anc, config, tune_config)
  File "/home/qc_whaley/dephased_ttn_project/uni_ttn/tf2.7/non_distributed_tunning/model.py", line 91, in __init__
    train_data, val_data, test_data = data.get_data_file(
  File "/home/qc_whaley/dephased_ttn_project/uni_ttn/tf2.7/non_distributed_tunning/data.py", line 144, in get_data_file
    (test_raw_im, test_raw_lab) = load_data(data_path + '_test')
  File "/home/qc_whaley/dephased_ttn_project/uni_ttn/tf2.7/non_distributed_tunning/data.py", line 189, in load_data
    data = pk.load(dest)
  File "/home/qc_whaley/anaconda3/envs/tf2.6/lib/python3.9/site-packages/ray/worker.py", line 425, in sigterm_handler
    sys.exit(1)
SystemExit: 1
