Failure # 1 (occurred at 2022-03-09_07-41-38)
Traceback (most recent call last):
  File "/home/qc_whaley/anaconda3/envs/tf2.6/lib/python3.9/site-packages/ray/tune/trial_runner.py", line 739, in _process_trial
    results = self.trial_executor.fetch_result(trial)
  File "/home/qc_whaley/anaconda3/envs/tf2.6/lib/python3.9/site-packages/ray/tune/ray_trial_executor.py", line 746, in fetch_result
    result = ray.get(trial_future[0], timeout=DEFAULT_GET_TIMEOUT)
  File "/home/qc_whaley/anaconda3/envs/tf2.6/lib/python3.9/site-packages/ray/_private/client_mode_hook.py", line 82, in wrapper
    return func(*args, **kwargs)
  File "/home/qc_whaley/anaconda3/envs/tf2.6/lib/python3.9/site-packages/ray/worker.py", line 1623, in get
    raise value
ray.exceptions.RayActorError: The actor died because of an error raised in its creation task, [36mray::UniTTN.__init__()[39m (pid=130723, ip=10.128.0.8)
  File "/home/qc_whaley/anaconda3/envs/tf2.6/lib/python3.9/site-packages/ray/tune/trainable.py", line 103, in __init__
    self.setup(copy.deepcopy(self.config))
  File "/home/qc_whaley/dephased_ttn_project/uni_ttn/tf2.7/non_distributed_tunning/model.py", line 219, in setup
    self.model = Model(data_path, digits, val_split, deph_p, num_anc, config, tune_config)
  File "/home/qc_whaley/dephased_ttn_project/uni_ttn/tf2.7/non_distributed_tunning/model.py", line 118, in __init__
    self.network = network.Network(num_pixels, deph_p, num_anc, config, tune_config)
  File "/home/qc_whaley/dephased_ttn_project/uni_ttn/tf2.7/non_distributed_tunning/network.py", line 25, in __init__
    self.layers.append(Layer(self.list_num_nodes[i], i, self.num_anc, self.init_mean, tune_config['tune_init_std']))
  File "/home/qc_whaley/dephased_ttn_project/uni_ttn/tf2.7/non_distributed_tunning/network.py", line 139, in __init__
    tf.random_normal_initializer(mean=init_mean, stddev=init_std)(
  File "/home/qc_whaley/anaconda3/envs/tf2.6/lib/python3.9/site-packages/tensorflow/python/ops/init_ops_v2.py", line 419, in __call__
    return self._random_generator.random_normal(shape, self.mean, self.stddev,
  File "/home/qc_whaley/anaconda3/envs/tf2.6/lib/python3.9/site-packages/tensorflow/python/ops/init_ops_v2.py", line 1072, in random_normal
    return op(
  File "/home/qc_whaley/anaconda3/envs/tf2.6/lib/python3.9/site-packages/tensorflow/python/util/dispatch.py", line 206, in wrapper
    return target(*args, **kwargs)
  File "/home/qc_whaley/anaconda3/envs/tf2.6/lib/python3.9/site-packages/tensorflow/python/ops/random_ops.py", line 97, in random_normal
    value = math_ops.add(mul, mean_tensor, name=name)
  File "/home/qc_whaley/anaconda3/envs/tf2.6/lib/python3.9/site-packages/tensorflow/python/util/dispatch.py", line 206, in wrapper
    return target(*args, **kwargs)
  File "/home/qc_whaley/anaconda3/envs/tf2.6/lib/python3.9/site-packages/tensorflow/python/ops/math_ops.py", line 3943, in add
    return gen_math_ops.add_v2(x, y, name=name)
  File "/home/qc_whaley/anaconda3/envs/tf2.6/lib/python3.9/site-packages/tensorflow/python/ops/gen_math_ops.py", line 455, in add_v2
    _ops.raise_from_not_ok_status(e, name)
  File "/home/qc_whaley/anaconda3/envs/tf2.6/lib/python3.9/site-packages/tensorflow/python/framework/ops.py", line 6941, in raise_from_not_ok_status
    six.raise_from(core._status_to_exception(e.code, message), None)
  File "<string>", line 3, in raise_from
tensorflow.python.framework.errors_impl.ResourceExhaustedError: failed to allocate memory [Op:AddV2]

