Failure # 1 (occurred at 2022-05-04_22-19-44)
Traceback (most recent call last):
  File "/home/qc_whaley/anaconda3/envs/tf2.6/lib/python3.9/site-packages/ray/tune/trial_runner.py", line 739, in _process_trial
    results = self.trial_executor.fetch_result(trial)
  File "/home/qc_whaley/anaconda3/envs/tf2.6/lib/python3.9/site-packages/ray/tune/ray_trial_executor.py", line 746, in fetch_result
    result = ray.get(trial_future[0], timeout=DEFAULT_GET_TIMEOUT)
  File "/home/qc_whaley/anaconda3/envs/tf2.6/lib/python3.9/site-packages/ray/_private/client_mode_hook.py", line 82, in wrapper
    return func(*args, **kwargs)
  File "/home/qc_whaley/anaconda3/envs/tf2.6/lib/python3.9/site-packages/ray/worker.py", line 1623, in get
    raise value
ray.exceptions.RayActorError: The actor died because of an error raised in its creation task, [36mray::MERA.__init__()[39m (pid=15529, ip=10.128.0.8)
RuntimeError: The actor with name MERA failed to be imported, and so cannot execute this method.

