Failure # 1 (occurred at 2022-03-09_07-37-43)
Traceback (most recent call last):
  File "/home/qc_whaley/anaconda3/envs/tf2.6/lib/python3.9/site-packages/ray/tune/trial_runner.py", line 739, in _process_trial
    results = self.trial_executor.fetch_result(trial)
  File "/home/qc_whaley/anaconda3/envs/tf2.6/lib/python3.9/site-packages/ray/tune/ray_trial_executor.py", line 746, in fetch_result
    result = ray.get(trial_future[0], timeout=DEFAULT_GET_TIMEOUT)
  File "/home/qc_whaley/anaconda3/envs/tf2.6/lib/python3.9/site-packages/ray/_private/client_mode_hook.py", line 82, in wrapper
    return func(*args, **kwargs)
  File "/home/qc_whaley/anaconda3/envs/tf2.6/lib/python3.9/site-packages/ray/worker.py", line 1621, in get
    raise value.as_instanceof_cause()
ray.exceptions.RayTaskError(AssertionError): [36mray::UniTTN.train_buffered()[39m (pid=118392, ip=10.128.0.8, repr=<model.UniTTN object at 0x7f80946f3340>)
  File "/home/qc_whaley/anaconda3/envs/tf2.6/lib/python3.9/site-packages/ray/tune/trainable.py", line 178, in train_buffered
    result = self.train()
  File "/home/qc_whaley/anaconda3/envs/tf2.6/lib/python3.9/site-packages/ray/tune/trainable.py", line 237, in train
    result = self.step()
  File "/home/qc_whaley/dephased_ttn_project/uni_ttn/tf2.7/non_distributed_tunning/model.py", line 222, in step
    self.model.run_epoch(batch_size, grad_accumulation=config['data']['grad_accumulation'])
  File "/home/qc_whaley/dephased_ttn_project/uni_ttn/tf2.7/non_distributed_tunning/model.py", line 183, in run_epoch
    assert not batch_size % exec_batch_size, 'batch_size not divisible by exec_batch_size'
AssertionError: batch_size not divisible by exec_batch_size

