[ERROR 2022-04-05 19:40:16,777] import_thread.py: 88  ImportThread: Connection closed by server.
Traceback (most recent call last):
  File "python/ray/_raylet.pyx", line 490, in ray._raylet.execute_task
  File "python/ray/_raylet.pyx", line 497, in ray._raylet.execute_task
  File "python/ray/_raylet.pyx", line 501, in ray._raylet.execute_task
  File "python/ray/_raylet.pyx", line 451, in ray._raylet.execute_task.function_executor
  File "/home/haoranliao/anaconda3/envs/tf2.7/lib/python3.9/site-packages/ray/_private/function_manager.py", line 563, in actor_method_executor
    return method(__ray_actor, *args, **kwargs)
  File "/home/haoranliao/anaconda3/envs/tf2.7/lib/python3.9/site-packages/ray/tune/trainable.py", line 173, in train_buffered
    result = self.train()
  File "/home/haoranliao/anaconda3/envs/tf2.7/lib/python3.9/site-packages/ray/tune/trainable.py", line 232, in train
    result = self.step()
  File "/tmp/pycharm_project_948/uni_ttn/tf2.7/non_distributed_tunning/model.py", line 225, in step
    self.model.run_epoch(batch_size, 0, grad_accumulation=config['data']['grad_accumulation'])
  File "/tmp/pycharm_project_948/uni_ttn/tf2.7/non_distributed_tunning/model.py", line 189, in run_epoch
    self.network.update(train_image_batch, train_label_batch, epoch, apply_grads=False)
  File "/tmp/pycharm_project_948/uni_ttn/tf2.7/non_distributed_tunning/model.py", line 189, in run_epoch
    self.network.update(train_image_batch, train_label_batch, epoch, apply_grads=False)
  File "/home/haoranliao/anaconda3/envs/tf2.7/lib/python3.9/bdb.py", line 88, in trace_dispatch
    return self.dispatch_line(frame)
  File "/home/haoranliao/anaconda3/envs/tf2.7/lib/python3.9/bdb.py", line 112, in dispatch_line
    self.user_line(frame)
  File "/home/haoranliao/anaconda3/envs/tf2.7/lib/python3.9/pdb.py", line 262, in user_line
    self.interaction(frame, None)
  File "/home/haoranliao/anaconda3/envs/tf2.7/lib/python3.9/pdb.py", line 357, in interaction
    self._cmdloop()
  File "/home/haoranliao/anaconda3/envs/tf2.7/lib/python3.9/pdb.py", line 322, in _cmdloop
    self.cmdloop()
  File "/home/haoranliao/anaconda3/envs/tf2.7/lib/python3.9/cmd.py", line 126, in cmdloop
    line = input(self.prompt)
OSError: [Errno 5] Input/output error

During handling of the above exception, another exception occurred:

Traceback (most recent call last):
  File "python/ray/_raylet.pyx", line 595, in ray._raylet.task_execution_handler
  File "python/ray/_raylet.pyx", line 453, in ray._raylet.execute_task
  File "python/ray/_raylet.pyx", line 552, in ray._raylet.execute_task
  File "/home/haoranliao/anaconda3/envs/tf2.7/lib/python3.9/site-packages/ray/_private/utils.py", line 103, in push_error_to_driver
    worker.core_worker.push_error(job_id, error_type, message, time.time())
  File "python/ray/_raylet.pyx", line 1722, in ray._raylet.CoreWorker.push_error
  File "python/ray/_raylet.pyx", line 161, in ray._raylet.check_status
ray.exceptions.RaySystemError: System error: Broken pipe

During handling of the above exception, another exception occurred:

Traceback (most recent call last):
  File "/home/haoranliao/anaconda3/envs/tf2.7/lib/python3.9/site-packages/ray/_private/utils.py", line 103, in push_error_to_driver
    worker.core_worker.push_error(job_id, error_type, message, time.time())
  File "python/ray/_raylet.pyx", line 1722, in ray._raylet.CoreWorker.push_error
  File "python/ray/_raylet.pyx", line 161, in ray._raylet.check_status
ray.exceptions.RaySystemError: System error: Broken pipe
Exception ignored in: 'ray._raylet.task_execution_handler'
Traceback (most recent call last):
  File "/home/haoranliao/anaconda3/envs/tf2.7/lib/python3.9/site-packages/ray/_private/utils.py", line 103, in push_error_to_driver
    worker.core_worker.push_error(job_id, error_type, message, time.time())
  File "python/ray/_raylet.pyx", line 1722, in ray._raylet.CoreWorker.push_error
  File "python/ray/_raylet.pyx", line 161, in ray._raylet.check_status
ray.exceptions.RaySystemError: System error: Broken pipe
